Workbook

Sheet 投放明细表
A1: 基础信息 | G1: 内容信息 | I1: 费用数据 | P1: 效率指标
A2: 投放日期 | B2: 所属周 | C2: 平台 | D2: 达人ID | E2: 达人姓名 | F2: 内容链接 | G2: 款式编号 | H2: 内容类型 | I2: 达人合作费 | J2: 平台投放费 | K2: 样品/运费成本 | L2: 点击量 | M2: 点赞数 | N2: 收藏数 | O2: 评论数 | P2: 总互动量 | Q2: 互动率 | R2: 单互动成本
A3: 2026-01-01 | B3: 1周 | C3: 抖音 | F3: https://v.douyin.com/iAq4s_v7QHs/ | G3: 000A1 | H3: 文严文 | K3: 107.5 | L3: 7172 | M3: 395 | N3: 31 | O3: 16 | P3: =IF(AND(M3<>"",M3>0),M3+N3+O3,"") | Q3: =IF(AND(L3<>"",L3>0,P3<>""),P3/L3,"") | R3: =IF(AND(P3<>"",P3>0),(I3+J3+K3)/P3,"")
A4: 2026-01-01 | B4: 1周 | C4: 抖音 | F4: https://v.douyin.com/MSVmmfdkbVo/ | G4: 0001A1 | H4: 文严文 | K4: 107.5 | L4: 13000 | M4: 1051 | N4: 31 | O4: 43 | P4: =IF(AND(M4<>"",M4>0),M4+N4+O4,"") | Q4: =IF(AND(L4<>"",L4>0,P4<>""),P4/L4,"") | R4: =IF(AND(P4<>"",P4>0),(I4+J4+K4)/P4,"")
A5: 2026-01-01 | B5: 1周 | C5: 抖音 | F5: https://v.douyin.com/y3HUBilSJ-o/ | G5: 0001A1 | H5: 文严文 | K5: 107.5 | L5: 2500 | M5: 182 | N5: 5 | O5: 7 | P5: =IF(AND(M5<>"",M5>0),M5+N5+O5,"") | Q5: =IF(AND(L5<>"",L5>0,P5<>""),P5/L5,"") | R5: =IF(AND(P5<>"",P5>0),(I5+J5+K5)/P5,"")
A6: 2026-01-01 | B6: 1周 | C6: 抖音 | F6: https://v.douyin.com/sBAtJ5NSdU4/ | G6: 0001A1 | H6: 文严文 | K6: 107.5 | L6: 495 | M6: 39 | N6: 7 | O6: 6 | P6: =IF(AND(M6<>"",M6>0),M6+N6+O6,"") | Q6: =IF(AND(L6<>"",L6>0,P6<>""),P6/L6,"") | R6: =IF(AND(P6<>"",P6>0),(I6+J6+K6)/P6,"")
A7: 2026-01-01 | B7: 1周 | C7: 抖音 | F7: https://v.douyin.com/PbZ_SSzunx4/ | G7: 0001A1 | H7: 文严文 | K7: 107.5 | L7: 20000 | M7: 801 | N7: 55 | O7: 27 | P7: =IF(AND(M7<>"",M7>0),M7+N7+O7,"") | Q7: =IF(AND(L7<>"",L7>0,P7<>""),P7/L7,"") | R7: =IF(AND(P7<>"",P7>0),(I7+J7+K7)/P7,"")
A8: 2026-01-01 | B8: 1周 | C8: 抖音 | F8: https://v.douyin.com/YqtYSfjlS3E/ | G8: 0001A1 | H8: 文严文 | K8: 107.5 | L8: 500 | M8: 20 | N8: 1 | O8: 9 | P8: =IF(AND(M8<>"",M8>0),M8+N8+O8,"") | Q8: =IF(AND(L8<>"",L8>0,P8<>""),P8/L8,"") | R8: =IF(AND(P8<>"",P8>0),(I8+J8+K8)/P8,"")
A9: 2026-01-01 | B9: 1周 | C9: 抖音 | F9: https://v.douyin.com/-7BMiMRloiA/ | G9: 0001A1 | H9: 文严文 | K9: 107.5 | L9: 1500 | M9: 135 | N9: 5 | O9: 3 | P9: =IF(AND(M9<>"",M9>0),M9+N9+O9,"") | Q9: =IF(AND(L9<>"",L9>0,P9<>""),P9/L9,"") | R9: =IF(AND(P9<>"",P9>0),(I9+J9+K9)/P9,"")
A10: 2026-01-02 | B10: 1周 | C10: 抖音 | F10: https://v.douyin.com/_ZlCoCmlQak/ | G10: 0001A1 | H10: 文严文 | K10: 107.5 | L10: 1000 | M10: 154 | N10: 1 | O10: 18 | P10: =IF(AND(M10<>"",M10>0),M10+N10+O10,"") | Q10: =IF(AND(L10<>"",L10>0,P10<>""),P10/L10,"") | R10: =IF(AND(P10<>"",P10>0),(I10+J10+K10)/P10,"")
A11: 2026-01-02 | B11: 1周 | C11: 抖音 | F11: https://v.douyin.com/V8o0WChiMZI/ | G11: 0001A1 | H11: 文严文 | K11: 107.5 | L11: 1000 | M11: 63 | N11: 4 | O11: 5 | P11: =IF(AND(M11<>"",M11>0),M11+N11+O11,"") | Q11: =IF(AND(L11<>"",L11>0,P11<>""),P11/L11,"") | R11: =IF(AND(P11<>"",P11>0),(I11+J11+K11)/P11,"")
A12: 2026-01-02 | B12: 1周 | C12: 抖音 | F12: https://v.douyin.com/-bqQANPJZgo/ | G12: 1217W | H12: 杨博文 | K12: 54 | L12: 3950 | M12: 56 | N12: 0 | O12: 16 | P12: =IF(AND(M12<>"",M12>0),M12+N12+O12,"") | Q12: =IF(AND(L12<>"",L12>0,P12<>""),P12/L12,"") | R12: =IF(AND(P12<>"",P12>0),(I12+J12+K12)/P12,"")
A13: 2026-01-02 | B13: 1周 | C13: 抖音 | F13: https://v.douyin.com/BV1jlAeIbuY/ | G13: 0001A1 | H13: 文严文 | K13: 107.5 | L13: 1275 | M13: 172 | N13: 2 | O13: 30 | P13: =IF(AND(M13<>"",M13>0),M13+N13+O13,"") | Q13: =IF(AND(L13<>"",L13>0,P13<>""),P13/L13,"") | R13: =IF(AND(P13<>"",P13>0),(I13+J13+K13)/P13,"")
A14: 2026-01-02 | B14: 1周 | C14: 抖音 | F14: https://v.douyin.com/iUlPRxVKQeU/ | G14: 495 | H14: 口播 | I14: 1000 | K14: 93 | L14: 303000 | M14: 13000 | N14: 1079 | O14: 124 | P14: =IF(AND(M14<>"",M14>0),M14+N14+O14,"") | Q14: =IF(AND(L14<>"",L14>0,P14<>""),P14/L14,"") | R14: =IF(AND(P14<>"",P14>0),(I14+J14+K14)/P14,"")
A15: 2026-01-02 | B15: 1周 | C15: 小红书 | F15: https://www.xiaohongshu.com/discovery/item/6957ad6c000000001e02382a?xsec_token=CB7z5rQCX629KondpFe6PuhJqLRd1NAcs3xKxQq6bKlzk=&xsec_source=app_share&type=video | G15: 495 | H15: 口播 | I15: 300 | K15: 93 | L15: 4364 | M15: 361 | N15: 189 | O15: 32 | P15: =IF(AND(M15<>"",M15>0),M15+N15+O15,"") | Q15: =IF(AND(L15<>"",L15>0,P15<>""),P15/L15,"") | R15: =IF(AND(P15<>"",P15>0),(I15+J15+K15)/P15,"")
A16: 2026-01-02 | B16: 1周 | C16: 小红书 | F16: https://www.xiaohongshu.com/discovery/item/6957c123000000001e02c96d?xsec_token=CBrSeaQKI4NDONmRGzS_ay9M7Y0vylVCzbmfkYZlmIL20=&xsec_source=app_share | G16: 495 | H16: 穿搭 | I16: 120 | K16: 93 | L16: 3759 | M16: 436 | N16: 117 | O16: 13 | P16: =IF(AND(M16<>"",M16>0),M16+N16+O16,"") | Q16: =IF(AND(L16<>"",L16>0,P16<>""),P16/L16,"") | R16: =IF(AND(P16<>"",P16>0),(I16+J16+K16)/P16,"")
A17: 2026-01-02 | B17: 1周 | C17: 小红书 | F17: https://www.xiaohongshu.com/discovery/item/6957d5e6000000002103fa96?xsec_token=CBYfSKHbvyxrrScDjtB8lffVUagleEJuvM8nGcParZ29w=&xsec_source=app_share&type=video | G17: 1217W | H17: 杨博文 | K17: 54 | L17: 158 | M17: 14 | N17: 3 | O17: 0 | P17: =IF(AND(M17<>"",M17>0),M17+N17+O17,"") | Q17: =IF(AND(L17<>"",L17>0,P17<>""),P17/L17,"") | R17: =IF(AND(P17<>"",P17>0),(I17+J17+K17)/P17,"")
A18: 2026-01-03 | B18: 1周 | C18: 抖音 | F18: https://v.douyin.com/SkcssLfRA0A/ | G18: 0001A1 | H18: 文严文 | K18: 107.5 | L18: 602 | M18: 26 | N18: 3 | O18: 19 | P18: =IF(AND(M18<>"",M18>0),M18+N18+O18,"") | Q18: =IF(AND(L18<>"",L18>0,P18<>""),P18/L18,"") | R18: =IF(AND(P18<>"",P18>0),(I18+J18+K18)/P18,"")
A19: 2026-01-03 | B19: 1周 | C19: 抖音 | F19: https://v.douyin.com/IzJdX82p4mw/ | G19: 493AX | H19: 穿搭 | K19: 98 | L19: 1831 | M19: 134 | N19: 3 | O19: 11 | P19: =IF(AND(M19<>"",M19>0),M19+N19+O19,"") | Q19: =IF(AND(L19<>"",L19>0,P19<>""),P19/L19,"") | R19: =IF(AND(P19<>"",P19>0),(I19+J19+K19)/P19,"")
A20: 2026-01-03 | B20: 1周 | C20: 抖音 | F20: https://v.douyin.com/rUAcExNJkKQ/ | G20: 0001A1 | H20: 新年好物 | K20: 107.5 | L20: 13000 | M20: 291 | N20: 77 | O20: 15 | P20: =IF(AND(M20<>"",M20>0),M20+N20+O20,"") | Q20: =IF(AND(L20<>"",L20>0,P20<>""),P20/L20,"") | R20: =IF(AND(P20<>"",P20>0),(I20+J20+K20)/P20,"")
A21: 2026-01-03 | B21: 1周 | C21: 抖音 | F21: https://v.douyin.com/cJTvVLIzgLw/ | G21: 493AX | H21: 穿搭 | K21: 98 | L21: 1000 | M21: 50 | N21: 2 | O21: 10 | P21: =IF(AND(M21<>"",M21>0),M21+N21+O21,"") | Q21: =IF(AND(L21<>"",L21>0,P21<>""),P21/L21,"") | R21: =IF(AND(P21<>"",P21>0),(I21+J21+K21)/P21,"")
A22: 2026-01-03 | B22: 1周 | C22: 抖音 | F22: https://v.douyin.com/lYBNGlgl0NU/ | G22: 0001A1 | H22: 文严文 | K22: 107.5 | L22: 2333 | M22: 354 | N22: 10 | O22: 40 | P22: =IF(AND(M22<>"",M22>0),M22+N22+O22,"") | Q22: =IF(AND(L22<>"",L22>0,P22<>""),P22/L22,"") | R22: =IF(AND(P22<>"",P22>0),(I22+J22+K22)/P22,"")
A23: 2026-01-03 | B23: 1周 | C23: 抖音 | F23: https://v.douyin.com/4CBvLPGC0ZI/ | G23: 495 | H23: 新年好物 | I23: 300 | K23: 93 | L23: 18000 | M23: 416 | N23: 167 | O23: 35 | P23: =IF(AND(M23<>"",M23>0),M23+N23+O23,"") | Q23: =IF(AND(L23<>"",L23>0,P23<>""),P23/L23,"") | R23: =IF(AND(P23<>"",P23>0),(I23+J23+K23)/P23,"")
A24: 2026-01-03 | B24: 1周 | C24: 抖音 | F24: https://v.douyin.com/osf5qWQPFkE/ | G24: 0001A1 | H24: 穿搭 | K24: 107.5 | L24: 14000 | M24: 924 | N24: 111 | O24: 19 | P24: =IF(AND(M24<>"",M24>0),M24+N24+O24,"") | Q24: =IF(AND(L24<>"",L24>0,P24<>""),P24/L24,"") | R24: =IF(AND(P24<>"",P24>0),(I24+J24+K24)/P24,"")
A25: 2026-01-03 | B25: 1周 | C25: 抖音 | F25: https://v.douyin.com/QJ8Yl1xI9cE/ | G25: 495 | H25: 穿搭 | I25: 20 | K25: 93 | L25: 9449 | M25: 296 | N25: 27 | O25: 27 | P25: =IF(AND(M25<>"",M25>0),M25+N25+O25,"") | Q25: =IF(AND(L25<>"",L25>0,P25<>""),P25/L25,"") | R25: =IF(AND(P25<>"",P25>0),(I25+J25+K25)/P25,"")
A26: 2026-01-03 | B26: 1周 | C26: 抖音 | F26: https://v.douyin.com/xoDXL9GJD0k/ | G26: 0001A1 | H26: 文严文 | K26: 107.5 | L26: 5102 | M26: 1022 | N26: 10 | O26: 29 | P26: =IF(AND(M26<>"",M26>0),M26+N26+O26,"") | Q26: =IF(AND(L26<>"",L26>0,P26<>""),P26/L26,"") | R26: =IF(AND(P26<>"",P26>0),(I26+J26+K26)/P26,"")
A27: 2026-01-03 | B27: 1周 | C27: 抖音 | F27: https://v.douyin.com/2YJ15N_BR-s/ | G27: 0001A1 | H27: 穿搭 | I27: 150 | K27: 107.5 | L27: 11000 | M27: 1035 | N27: 59 | O27: 21 | P27: =IF(AND(M27<>"",M27>0),M27+N27+O27,"") | Q27: =IF(AND(L27<>"",L27>0,P27<>""),P27/L27,"") | R27: =IF(AND(P27<>"",P27>0),(I27+J27+K27)/P27,"")
A28: 2026-01-03 | B28: 1周 | C28: 抖音 | F28: https://v.douyin.com/XslTSsTit24/ | G28: 0001A1 | H28: 文严文 | K28: 107.5 | L28: 1280 | M28: 101 | N28: 2 | O28: 11 | P28: =IF(AND(M28<>"",M28>0),M28+N28+O28,"") | Q28: =IF(AND(L28<>"",L28>0,P28<>""),P28/L28,"") | R28: =IF(AND(P28<>"",P28>0),(I28+J28+K28)/P28,"")
A29: 2026-01-03 | B29: 1周 | C29: 抖音 | F29: https://v.douyin.com/1PcAmW41d4I/ | G29: 495 | H29: 穿搭 | K29: 93 | L29: 95000 | M29: 2009 | N29: 518 | O29: 68 | P29: =IF(AND(M29<>"",M29>0),M29+N29+O29,"") | Q29: =IF(AND(L29<>"",L29>0,P29<>""),P29/L29,"") | R29: =IF(AND(P29<>"",P29>0),(I29+J29+K29)/P29,"")
A30: 2026-01-03 | B30: 1周 | C30: 抖音 | F30: https://v.douyin.com/OyKLbv7VQAI/ | G30: 489Y | H30: 赵露思 | K30: 53.5 | L30: 3000 | M30: 165 | N30: 4 | O30: 5 | P30: =IF(AND(M30<>"",M30>0),M30+N30+O30,"") | Q30: =IF(AND(L30<>"",L30>0,P30<>""),P30/L30,"") | R30: =IF(AND(P30<>"",P30>0),(I30+J30+K30)/P30,"")
A31: 2026-01-03 | B31: 1周 | C31: 抖音 | F31: https://v.douyin.com/z677vQz_ZX4/ | G31: 0001A1 | H31: 文严文 | K31: 107.5 | L31: 1912 | M31: 142 | N31: 9 | O31: 10 | P31: =IF(AND(M31<>"",M31>0),M31+N31+O31,"") | Q31: =IF(AND(L31<>"",L31>0,P31<>""),P31/L31,"") | R31: =IF(AND(P31<>"",P31>0),(I31+J31+K31)/P31,"")
A32: 2026-01-03 | B32: 1周 | C32: 小红书 | F32: https://www.xiaohongshu.com/discovery/item/69585a75000000001e00544f?xsec_token=CBDgYDsKpY4fARgqZp-CQn40MEd2uZhBGh8Zxc_ojwweU=&xsec_source=app_share&type=video | G32: 495 | H32: 口播 | I32: 250 | K32: 93 | L32: 17108 | M32: 1177 | N32: 428 | O32: 26 | P32: =IF(AND(M32<>"",M32>0),M32+N32+O32,"") | Q32: =IF(AND(L32<>"",L32>0,P32<>""),P32/L32,"") | R32: =IF(AND(P32<>"",P32>0),(I32+J32+K32)/P32,"")
A33: 2026-01-03 | B33: 1周 | C33: 小红书 | F33: https://www.xiaohongshu.com/discovery/item/6958fd95000000001d03bb46?xsec_token=CBtI3pB-Y_0lIL19kT25cWxtvSJknDiuoJq1gp6CUV4Vc=&xsec_source=app_share&type=video | G33: 0001A1 | H33: 穿搭 | I33: 300 | K33: 107.5 | L33: 15249 | M33: 1281 | N33: 664 | O33: 27 | P33: =IF(AND(M33<>"",M33>0),M33+N33+O33,"") | Q33: =IF(AND(L33<>"",L33>0,P33<>""),P33/L33,"") | R33: =IF(AND(P33<>"",P33>0),(I33+J33+K33)/P33,"")
A34: 2026-01-04 | B34: 1周 | C34: 抖音 | F34: https://v.douyin.com/rggb7eesuWU/ | G34: 495 | H34: 穿搭 | I34: 100 | K34: 93 | L34: 28000 | M34: 1952 | N34: 342 | O34: 44 | P34: =IF(AND(M34<>"",M34>0),M34+N34+O34,"") | Q34: =IF(AND(L34<>"",L34>0,P34<>""),P34/L34,"") | R34: =IF(AND(P34<>"",P34>0),(I34+J34+K34)/P34,"")
A35: 2026-01-04 | B35: 1周 | C35: 抖音 | F35: https://v.douyin.com/WpHk0afBuOs/ | G35: 0001A1 | H35: 穿搭 | K35: 107.5 | L35: 7000 | M35: 170 | N35: 5 | O35: 40 | P35: =IF(AND(M35<>"",M35>0),M35+N35+O35,"") | Q35: =IF(AND(L35<>"",L35>0,P35<>""),P35/L35,"") | R35: =IF(AND(P35<>"",P35>0),(I35+J35+K35)/P35,"")
A36: 2026-01-04 | B36: 1周 | C36: 抖音 | F36: https://v.douyin.com/r0Kr4KyY2OE/ | G36: 495 | H36: 穿搭 | K36: 93 | L36: 17000 | M36: 1140 | N36: 100 | O36: 153 | P36: =IF(AND(M36<>"",M36>0),M36+N36+O36,"") | Q36: =IF(AND(L36<>"",L36>0,P36<>""),P36/L36,"") | R36: =IF(AND(P36<>"",P36>0),(I36+J36+K36)/P36,"")
A37: 2026-01-04 | B37: 1周 | C37: 抖音 | F37: https://v.douyin.com/T5g_YI_-xSw/ | G37: 0001A1 | H37: 穿搭 | K37: 107.5 | L37: 3973 | M37: 188 | N37: 57 | O37: 3 | P37: =IF(AND(M37<>"",M37>0),M37+N37+O37,"") | Q37: =IF(AND(L37<>"",L37>0,P37<>""),P37/L37,"") | R37: =IF(AND(P37<>"",P37>0),(I37+J37+K37)/P37,"")
A38: 2026-01-04 | B38: 1周 | C38: 抖音 | F38: https://v.douyin.com/mmBK772VbHE/ | G38: 495 | H38: 程相 | K38: 93 | L38: 2193 | M38: 34 | N38: 1 | O38: 4 | P38: =IF(AND(M38<>"",M38>0),M38+N38+O38,"") | Q38: =IF(AND(L38<>"",L38>0,P38<>""),P38/L38,"") | R38: =IF(AND(P38<>"",P38>0),(I38+J38+K38)/P38,"")
A39: 2026-01-04 | B39: 1周 | C39: 小红书 | F39: https://www.xiaohongshu.com/discovery/item/6959cc78000000001e02a003?xsec_token=CBg5TFQuZ372BLFvhRJZYNwrMeYGh5FRSZUpHfXASYbL0=&xsec_source=app_share | G39: 489Y | H39: 赵露思 | K39: 53.5 | L39: 1132 | M39: 105 | N39: 8 | O39: 4 | P39: =IF(AND(M39<>"",M39>0),M39+N39+O39,"") | Q39: =IF(AND(L39<>"",L39>0,P39<>""),P39/L39,"") | R39: =IF(AND(P39<>"",P39>0),(I39+J39+K39)/P39,"")
A40: 2026-01-04 | B40: 1周 | C40: 小红书 | F40: https://www.xiaohongshu.com/discovery/item/6959d71b000000001e03669f?xsec_token=CBimvAsSiO23cNWAhp8h_RL7bp4cWaOwmqBaLS1l4mZZQ=&xsec_source=app_share | G40: 0001A1 | H40: 穿搭 | K40: 107.5 | L40: 2550 | M40: 149 | N40: 59 | O40: 16 | P40: =IF(AND(M40<>"",M40>0),M40+N40+O40,"") | Q40: =IF(AND(L40<>"",L40>0,P40<>""),P40/L40,"") | R40: =IF(AND(P40<>"",P40>0),(I40+J40+K40)/P40,"")
...

Sheet 达人主数据
A1: 达人ID | B1: 达人姓名 | C1: 所属平台 | D1: 粉丝量级 | E1: 达人分级 | F1: 签约状态 | G1: 所属机构 | H1: 联系方式 | I1: 合作类型 | J1: 首次合作日期 | K1: 累计合作次数 | L1: 累计投放费用 | M1: 平均互动率 | N1: 备注
A2: （暂无达人数据，后续做达人投放时在此添加）
A3: ↓ 公式示例（后续添加达人时参考） ↓
A4: 示例：KOL001 | B4: 示例达人 | K4: =IF(A4<>"",COUNTIF(投放明细表!D:D,A4),"") | L4: =IF(A4<>"",SUMIF(投放明细表!D:D,A4,投放明细表!I:I)+SUMIF(投放明细表!D:D,A4,投放明细表!J:J)+SUMIF(投放明细表!D:D,A4,投放明细表!K:K),"") | M4: =IF(A4<>"",IFERROR(AVERAGEIF(投放明细表!D:D,A4,投放明细表!Q:Q),""),"")

Sheet 款式主数据
A1: 款式编号 | B1: 款式名称 | C1: 品类 | D1: 成本价 | E1: 售价 | F1: 毛利率 | G1: 上市时间 | H1: 主推平台 | I1: 状态 | J1: 累计投放费用 | K1: 累计互动量 | L1: 备注
A2: 495 | C2: 鞋 | D2: 93 | F2: =IF(AND(D2<>"",E2<>"",E2>0),(E2-D2)/E2,"") | H2: 抖音 | I2: 在推 | J2: =IF(A2<>"",SUMIF(投放明细表!G:G,A2,投放明细表!I:I)+SUMIF(投放明细表!G:G,A2,投放明细表!J:J)+SUMIF(投放明细表!G:G,A2,投放明细表!K:K),"") | K2: =IF(A2<>"",SUMIF(投放明细表!G:G,A2,投放明细表!P:P),"")
A3: 0002A1 | C3: 鞋 | D3: 110.5 | F3: =IF(AND(D3<>"",E3<>"",E3>0),(E3-D3)/E3,"") | H3: 抖音 | I3: 在推 | J3: =IF(A3<>"",SUMIF(投放明细表!G:G,A3,投放明细表!I:I)+SUMIF(投放明细表!G:G,A3,投放明细表!J:J)+SUMIF(投放明细表!G:G,A3,投放明细表!K:K),"") | K3: =IF(A3<>"",SUMIF(投放明细表!G:G,A3,投放明细表!P:P),"")
A4: 0001A1 | C4: 鞋 | D4: 107.5 | F4: =IF(AND(D4<>"",E4<>"",E4>0),(E4-D4)/E4,"") | H4: 抖音 | I4: 在推 | J4: =IF(A4<>"",SUMIF(投放明细表!G:G,A4,投放明细表!I:I)+SUMIF(投放明细表!G:G,A4,投放明细表!J:J)+SUMIF(投放明细表!G:G,A4,投放明细表!K:K),"") | K4: =IF(A4<>"",SUMIF(投放明细表!G:G,A4,投放明细表!P:P),"")
A5: 459 | C5: 鞋 | D5: 46.5 | F5: =IF(AND(D5<>"",E5<>"",E5>0),(E5-D5)/E5,"") | H5: 抖音 | I5: 在推 | J5: =IF(A5<>"",SUMIF(投放明细表!G:G,A5,投放明细表!I:I)+SUMIF(投放明细表!G:G,A5,投放明细表!J:J)+SUMIF(投放明细表!G:G,A5,投放明细表!K:K),"") | K5: =IF(A5<>"",SUMIF(投放明细表!G:G,A5,投放明细表!P:P),"")
A6: 0003A2 | C6: 鞋 | D6: 49.5 | F6: =IF(AND(D6<>"",E6<>"",E6>0),(E6-D6)/E6,"") | H6: 抖音 | I6: 在推 | J6: =IF(A6<>"",SUMIF(投放明细表!G:G,A6,投放明细表!I:I)+SUMIF(投放明细表!G:G,A6,投放明细表!J:J)+SUMIF(投放明细表!G:G,A6,投放明细表!K:K),"") | K6: =IF(A6<>"",SUMIF(投放明细表!G:G,A6,投放明细表!P:P),"")
A7: 489 | C7: 鞋 | D7: 53.5 | F7: =IF(AND(D7<>"",E7<>"",E7>0),(E7-D7)/E7,"") | H7: 抖音 | I7: 在推 | J7: =IF(A7<>"",SUMIF(投放明细表!G:G,A7,投放明细表!I:I)+SUMIF(投放明细表!G:G,A7,投放明细表!J:J)+SUMIF(投放明细表!G:G,A7,投放明细表!K:K),"") | K7: =IF(A7<>"",SUMIF(投放明细表!G:G,A7,投放明细表!P:P),"")
A8: 001A1 | C8: 鞋 | D8: 107.5 | F8: =IF(AND(D8<>"",E8<>"",E8>0),(E8-D8)/E8,"") | H8: 抖音 | I8: 在推 | J8: =IF(A8<>"",SUMIF(投放明细表!G:G,A8,投放明细表!I:I)+SUMIF(投放明细表!G:G,A8,投放明细表!J:J)+SUMIF(投放明细表!G:G,A8,投放明细表!K:K),"") | K8: =IF(A8<>"",SUMIF(投放明细表!G:G,A8,投放明细表!P:P),"")
A9: 1093W | C9: 鞋 | F9: =IF(AND(D9<>"",E9<>"",E9>0),(E9-D9)/E9,"") | H9: 抖音 | I9: 在推 | J9: =IF(A9<>"",SUMIF(投放明细表!G:G,A9,投放明细表!I:I)+SUMIF(投放明细表!G:G,A9,投放明细表!J:J)+SUMIF(投放明细表!G:G,A9,投放明细表!K:K),"") | K9: =IF(A9<>"",SUMIF(投放明细表!G:G,A9,投放明细表!P:P),"")
A10: 1217W | C10: 鞋 | D10: 54 | F10: =IF(AND(D10<>"",E10<>"",E10>0),(E10-D10)/E10,"") | H10: 抖音 | I10: 在推 | J10: =IF(A10<>"",SUMIF(投放明细表!G:G,A10,投放明细表!I:I)+SUMIF(投放明细表!G:G,A10,投放明细表!J:J)+SUMIF(投放明细表!G:G,A10,投放明细表!K:K),"") | K10: =IF(A10<>"",SUMIF(投放明细表!G:G,A10,投放明细表!P:P),"")
A11: 1225 | C11: 鞋 | D11: 55.5 | F11: =IF(AND(D11<>"",E11<>"",E11>0),(E11-D11)/E11,"") | H11: 抖音 | I11: 在推 | J11: =IF(A11<>"",SUMIF(投放明细表!G:G,A11,投放明细表!I:I)+SUMIF(投放明细表!G:G,A11,投放明细表!J:J)+SUMIF(投放明细表!G:G,A11,投放明细表!K:K),"") | K11: =IF(A11<>"",SUMIF(投放明细表!G:G,A11,投放明细表!P:P),"")
A12: 492 | C12: 鞋 | D12: 69.5 | F12: =IF(AND(D12<>"",E12<>"",E12>0),(E12-D12)/E12,"") | H12: 抖音 | I12: 在推 | J12: =IF(A12<>"",SUMIF(投放明细表!G:G,A12,投放明细表!I:I)+SUMIF(投放明细表!G:G,A12,投放明细表!J:J)+SUMIF(投放明细表!G:G,A12,投放明细表!K:K),"") | K12: =IF(A12<>"",SUMIF(投放明细表!G:G,A12,投放明细表!P:P),"")
A13: 1172W | C13: 鞋 | D13: 57.5 | F13: =IF(AND(D13<>"",E13<>"",E13>0),(E13-D13)/E13,"") | H13: 抖音 | I13: 在推 | J13: =IF(A13<>"",SUMIF(投放明细表!G:G,A13,投放明细表!I:I)+SUMIF(投放明细表!G:G,A13,投放明细表!J:J)+SUMIF(投放明细表!G:G,A13,投放明细表!K:K),"") | K13: =IF(A13<>"",SUMIF(投放明细表!G:G,A13,投放明细表!P:P),"")
A14: 486 | C14: 鞋 | D14: 52.5 | F14: =IF(AND(D14<>"",E14<>"",E14>0),(E14-D14)/E14,"") | H14: 抖音 | I14: 测试 | J14: =IF(A14<>"",SUMIF(投放明细表!G:G,A14,投放明细表!I:I)+SUMIF(投放明细表!G:G,A14,投放明细表!J:J)+SUMIF(投放明细表!G:G,A14,投放明细表!K:K),"") | K14: =IF(A14<>"",SUMIF(投放明细表!G:G,A14,投放明细表!P:P),"")
A15: 000A1 | C15: 鞋 | D15: 107.5 | F15: =IF(AND(D15<>"",E15<>"",E15>0),(E15-D15)/E15,"") | H15: 抖音 | I15: 测试 | J15: =IF(A15<>"",SUMIF(投放明细表!G:G,A15,投放明细表!I:I)+SUMIF(投放明细表!G:G,A15,投放明细表!J:J)+SUMIF(投放明细表!G:G,A15,投放明细表!K:K),"") | K15: =IF(A15<>"",SUMIF(投放明细表!G:G,A15,投放明细表!P:P),"")
A16: 493AX | C16: 鞋 | D16: 98 | F16: =IF(AND(D16<>"",E16<>"",E16>0),(E16-D16)/E16,"") | H16: 抖音 | I16: 测试 | J16: =IF(A16<>"",SUMIF(投放明细表!G:G,A16,投放明细表!I:I)+SUMIF(投放明细表!G:G,A16,投放明细表!J:J)+SUMIF(投放明细表!G:G,A16,投放明细表!K:K),"") | K16: =IF(A16<>"",SUMIF(投放明细表!G:G,A16,投放明细表!P:P),"")
A17: 489Y | C17: 鞋 | D17: 53.5 | F17: =IF(AND(D17<>"",E17<>"",E17>0),(E17-D17)/E17,"") | H17: 抖音 | I17: 测试 | J17: =IF(A17<>"",SUMIF(投放明细表!G:G,A17,投放明细表!I:I)+SUMIF(投放明细表!G:G,A17,投放明细表!J:J)+SUMIF(投放明细表!G:G,A17,投放明细表!K:K),"") | K17: =IF(A17<>"",SUMIF(投放明细表!G:G,A17,投放明细表!P:P),"")
A18: 1227W | C18: 鞋 | D18: 61 | F18: =IF(AND(D18<>"",E18<>"",E18>0),(E18-D18)/E18,"") | H18: 小红书 | I18: 测试 | J18: =IF(A18<>"",SUMIF(投放明细表!G:G,A18,投放明细表!I:I)+SUMIF(投放明细表!G:G,A18,投放明细表!J:J)+SUMIF(投放明细表!G:G,A18,投放明细表!K:K),"") | K18: =IF(A18<>"",SUMIF(投放明细表!G:G,A18,投放明细表!P:P),"")
A19: 1225W | C19: 鞋 | D19: 60.5 | F19: =IF(AND(D19<>"",E19<>"",E19>0),(E19-D19)/E19,"") | H19: 抖音 | I19: 测试 | J19: =IF(A19<>"",SUMIF(投放明细表!G:G,A19,投放明细表!I:I)+SUMIF(投放明细表!G:G,A19,投放明细表!J:J)+SUMIF(投放明细表!G:G,A19,投放明细表!K:K),"") | K19: =IF(A19<>"",SUMIF(投放明细表!G:G,A19,投放明细表!P:P),"")

Sheet 更新指南
A1: 📋 达人投放数据 - 使用指南
A3: 一、文件结构
A4: 1. 投放明细表 - 每条投放记录一行（1-7月历史数据已填充）
A5: 2. 达人主数据 - 目前暂无达人维度数据，后续做达人投放时在此维护
A6: 3. 款式主数据 - 18个款式，累计数据自动联动更新
A7: 4. 更新指南 - 本页
A9: 二、字段映射说明（原始数据 → 新模板）
A10: 日期 → 投放日期
A11: （计算）→ 所属周（根据日期自动算出第几周）
A12: 平台 → 平台
A13: （暂无）→ 达人ID / 达人姓名（留空）
A14: 发布链接 → 内容链接
... A31: 款式主数据的累计值会自动更新
